Workbook

Sheet Cover
A5: K-Beauty & Medical Premium Tour Package for Muslim VIP Clients
A21: 2026.02.13
B27: Package Highlights (Trust + Religious Reassurance + Premium Value)
C31: ✔ Halal & Muslim-Friendly Services (Verified Partners)
C32: ✔ Privacy & Gender-Sensitive Care
C33: ✔ Female Doctor & Therapist Options
C34: ✔ Alcohol-Free Medical & Beauty Products (on request)
C35: ✔ Luxury Hotel Accommodation
C36: ✔ Private Vehicle Service
C37: – Optional Halal-Certified Limousine (Prayer Space Available)
C38: ✔ Fully Private Schedule
C39: ✔ Halal Dining Arrangements & Muslim-Friendly Options
C40: ✔ Arabic / English Coordination Support
C41: ✔ Prayer Times Considered in Daily Schedule
C42: ✔ Transparent Pricing
B47: Travel & Service Overview
B48: (Basic Information for Service Coordination)
B51: 1. | C51: Concept | D51: : K-Beauty + Medical + Wellness (Tour / Leisure / K-Pop Experience) + Luxury
B53: 2. | C53: Destination & Travelers
B54: ● | C54: Destination | D54: : Republic of Korea
B55: ● | C55: Total Travelers | D55: : [ ] Persons (Family / Companion / Others: [ ] )
B57: 3. | C57: Flight Schedule
B58: ● | C58: OUT(Outbound) | D58: : Departure - Mar. 10. 2026. 03:30 (Dubai) / Arrival - Mar. 10. 2026. 16:50 (Incheon)
B59: ● | C59: IN(Inbound) | D59: : Departure - Mar. 19. 2026. 23:40 (Incheon) / Arrival - Mar. 20. 2026. 05:05 (Dubai)
B61: 4. | C61: Prepared by
B62: ● | C62: Agent Name / Company | D62: :
B63: ● | C63: Meeting Date | D63: :
B66: VIP Essentials & Preferences
B68: 1. | C68: VIP Information
B69: ● | C69: Full name | D69: : Michael Hong
B70: ● | C70: Gender | D70: [ ] Male / [ ] Female
B71: ● | C71: Date of Birth | D71: : Feb. OO, 197X(Age: 5X)
B72: ● | C72: Nationality | D72: : Korean
B73: ● | C73: Passport No | D73: : DMC 0000000000
B75: 2. | C75: Contact Information
B76: ● | C76: Phone Number | D76: : +971-00-00-000
B77: ● | C77: Email Address | D77: : example@example.com
B78: ● | C78: Emergency Contact | D78: : Name: [ ] / Relation: [ ] / Phone: [ ]
B80: 3. | C80: Medical & Special Information
B81: ● | C81: Health Conditions | D81: : | E81: ● | F81: Medical Restrictions | G81: :
...

Sheet (1) Selection_K-Medical
A1: K-Medical Selection Sheet for Schedule
B3: Name (M or F) : | C3: =Cover!$D$69 -> : Michael Hong | F3: Passport No. : | G3: =Cover!$D$73 -> : DMC 0000000000
B4: Birth Date : | C4: =Cover!$D$71 -> : Feb. OO, 197X(Age: 5X) | F4: Arrival Flight Schedule (Local Time): | G4: =Cover!$D$58 -> : Departure - Mar. 10. 2026. 03:30 (Dubai) / Arrival - Mar. 10. 2026. 16:50 (Incheon)
B5: VIPs Contact. : | C5: =_xlfn.TEXTJOIN(" / ", TRUE, Cover!$D$76:$D$77) -> : +971-00-00-000 / : example@example.com | F5: Departure Flight Schedule (Local Time) : | G5: =Cover!$D$59 -> : Departure - Mar. 19. 2026. 23:40 (Incheon) / Arrival - Mar. 20. 2026. 05:05 (Dubai)
A7: Premium Package Category | F7: Check (ex.) | G7: Remarks | H7: Customer Requirement
A8: Package | C8: Package detail | D8: Duration | E8: Estimated Price (USD)
A9: K-Medical | B9: Silver | C9: Purpose * Quick overview of current health status * Early detection of basic health risks * Entry-level screening with minimal time and burden Core Inclusions * Physical measurements (height, weight, BMI, blood pressure) * Basic blood tests (liver, kidney, glucose, lipid profile) * Urinalysis * Chest X-ray * Basic consultation | D9: 1day | E9: M: 990 - 1,200 F: 1,110 - 1733.33 | G9: Surgery excluded After the medical check-up, please indicate whether you would prefer to rest at the hospital or at your hotel.
B10: Gold | C10: Purpose * Early detection of common diseases * In-depth evaluation of major organs * Most common comprehensive check-up level in Korea Core Inclusions * All BASIC items * Abdominal ultrasound * Gastroscopy / Colonoscopy (or alternatives) * Cardiovascular tests (ECG, arteriosclerosis) * Cancer screening (age & gender-based) * Specialist consultation | D10: 1day | E10: M: 3,506.53 - 12,376 F: 3,900 - 12,000
A11: Premium Package Category | F11: Check (ex.) | G11: Remarks | H11: Customer Requirement
A12: Package | C12: Package detail | D12: Duration | E12: Estimated Price (USD)
A13: K-Medical | B13: Diamond (Premium) | C13: Purpose * High-precision diagnostics and personalized risk assessment * Prediction and prevention of future health issues * VIP-level medical experience Core Inclusions * All STANDARD items * Advanced imaging (CT, MRI, heart/brain scans) * Advanced cancer screening panels * Hormone, immune, metabolic analysis * Optional genetic testing * One-on-one expert consultation * Personalized health report | D13: Min.2day | E13: M: 11,519.20 - 16,818.67 F: 12,518.80 - 17,294.67 | F13: ✔ | G13: Surgery excluded After the medical check-up, please indicate whether you would prefer to rest at the hospital or at your hotel.

Sheet (2) Selection_K-Beauty_Medical
A1: K-Medical Selection Sheet for Schedule
C3: Name (M or F) : | D3: =Cover!$D$69 -> : Michael Hong | G3: Passport No. : | H3: =Cover!$D$73 -> : DMC 0000000000
C4: Birth Date : | D4: =Cover!$D$71 -> : Feb. OO, 197X(Age: 5X) | G4: Arrival Flight Schedule (Local Time): | H4: =Cover!$D$58 -> : Departure - Mar. 10. 2026. 03:30 (Dubai) / Arrival - Mar. 10. 2026. 16:50 (Incheon)
C5: VIPs Contact. : | D5: =_xlfn.TEXTJOIN(" / ", TRUE, Cover!$D$76:$D$77) -> : +971-00-00-000 / : example@example.com | G5: Departure Flight Schedule (Local Time) : | H5: =Cover!$D$59 -> : Departure - Mar. 19. 2026. 23:40 (Incheon) / Arrival - Mar. 20. 2026. 05:05 (Dubai)
A8: Premium Package Category | G8: Check (ex.) | H8: Remarks | I8: Customer Requirement
A9: Package | D9: Package detail | E9: Duration | F9: Estimated Price (USD)
A10: K-Beauty (Medical) | B10: A Clinic | C10: Juvénile | D10: "A Clinic" is the VVIP stem cell center at "A Clinic", offering an exclusive private regenerative program that rejuvenates not only the skin but your entire body. Moving beyond simple treatments, our program is built on precise stem-cell-based solutions that address the root causes of aging, helping you preserve firm, radiant skin and enhance your overall wellness.
C11: All-Layer | D11: All-Layer is our specialized lifting and tightening center, dedicated to refining your natural beauty by precisely treating every layer of the skin — from the surface to the deep muscle tissue. Beyond superficial improvements, we perform a comprehensive, multi-layer analysis of your skin’s structure to deliver a fully personalized solution. This approach restores harmonious balance to your facial volume, elasticity, and texture.
C12: Sportif | D12: "A Clinic" is a specialized total body conditioning center for professional athletes needing pre/post-game care, and for individuals seeking recovery after physical activities such as tennis and golf. We provide personalized care designed to maximize athletic performance, including rapid post-workout recovery, muscle fatigue relief, and body contour refinement. Our tailored solutions encompass everything from pre- and post-competition care for athletes, diet management, postpartum recovery, to body contouring.
C13: Glow Package | D13: Ultherapy 400 shots + Sofwave 300 pulses + Eye Thermage 450 shots + Premium Rejuran Glow Toxin + Premium Skin Care Treatment | E13: 120m | F13: 6666.67
C14: Premium Anti-Aging Package | D14: Stem Cell IV Therapy + Ultherapy 400 shots + Sofwave 300 pulses + Eye Thermage 450 shots + Titanium or BBL Hero + Premium Rejuran Glow Toxin + Premium Skin Care Treatment | E14: 180m | F14: 13333.33
C15: Premium Stem Cell Anti-Aging Package | D15: Activated Stem Cell IV Therapy + Stem Cell Facial Treatment + Ultherapy 600 shots + Sofwave 300 pulses + Titanium or BBL Hero + Premium Skin Care Treatment | E15: 180m | F15: 20000
C16: Premiun Body Package | D16: Ultherapy Prime 3,000 shots (Abdomen, Arms, Thighs) + Sofwave 1,500 pulses (Abdomen, Arms, Thighs) + Full Body BBL HERO + Manual Body Treatment + Hyperbaric Oxygen Therapy + Stem Cell IV Therapy + Premium Skin Care Treatment | E16: 480m | F16: 33333.33 | G16: ✔
A19: Premium Package Category | G19: Check (ex.) | H19: Remarks | I19: Customer Requirement
A20: Package | D20: Package detail | E20: Duration | F20: Estimated Price (USD)
A21: K-Beauty (Medical) | B21: B Clinic | C21: Special (Stem Cell) | D21: Blood Stem Cell Full Face + Stem cell intravenous injection + Premium SkinCeuticals Antioxidant Care | E21: 120m
C22: Basic | D22: S-1 or S-2 + Basic : 1 vial Sculptra or Juvederm Filler 3cc (No restrictions on body part) + Premium SkinCeuticals Antioxidant Care | E22: 120m | F22: 15,866.67 - 23,800
C23: Gold | D23: S-1 or S-2 + Gold : Rejuran HB 4cc + Full Face Skin Botox + Thermage FLX 900 Shot(Face+Neck)+ 1 vial Sculptra (No restrictions on body part) + Premium SkinCeuticals Antioxidant Care | E23: 120m | F23: 23,800 - 31,733.33
C24: Platinum | D24: S-1 or S-2 + Platinum : Rejuran HB 4cc + Full Face Skin Botox + Ultherapy HIFU Prime 600 shot + Thermage FLX 900 Shot(Face+Neck) + Premium SkinCeuticals Antioxidant Care + Premium SkinCeuticals(55ml) Ampoule giveaway | E24: 180m | F24: 31,733.33 - 39,666.67 | G24: ✔
B25: C Clinic | C25: Royal Refresh Day (Face only, no injection) | D25: Ultherapy Prime 600 shots, Thermage 600 shots, Eye Thermage 225 shots, LDM therapy (12 minutes), Radio-Frequency facial care, 24K Gold Therapy, Regenerative LED treatment | E25: 180m | F25: 7933.33
C26: Royal Signature Lifting (Including neck & fatigue recovery) | D26: Ultherapy Prime 600 shots, Ultherapy Prime 200 shots (Neck), Eye Ultherapy Prime 200 shots Thermage 600 shots, Volumer 200 shots (Neck), Eye Thermage 225 shots, Titanium 100 kJ Pico Toning, Rejuran Healer 4cc, Rejuran Eye 2cc, Juvelook Skin 4cc, Mega Complex Vitamin IV Therapy, Premium Nutrition IV Therapy, RejuDM Premium Care(24K Gold therapy+Cryo therapy+LDM Rejuran Skin Booster(2 vials)+LED light therapy+Modeling pack) Radio-Frequency facial & neck care | E26: 240m | F26: 15866.67
C27: Royal Face & Body Refinement (Royal Hospital Takeover) | D27: Ultherapy Prime 600 shots, Ultherapy Prime 200 shots (Neck), Eye Ultherapy Prime 200 shots Thermage 600 shots, Volumer 200 shots (Neck), Eye Thermage 225 shots, Titanium 100 kJ Pico Dual Toning, Rejuran Healer 4cc, Rejuran Eye 2cc, Juvelook Skin 4cc Mega Complex Vitamin IV Therapy, Premium Nutrition IV Therapy RejuDM Premium Care(24K Gold therapy+Cryo therapy+LDM Rejuran Skin Booster(2 vials)+LED light therapy+Modeling pack) Radio-Frequency facial & neck care, Ultrasound facial & neck care | E27: 540m | F27: 23800 | G27: ✔

Sheet Information_K-Beauty_Medical
A1: K-Beauty_Medical Information for Schedule
A5: K-Beauty Dermatology Clinic Category
A6: Package | D6: Treatment Objective | E6: Signature Treatments | F6: Key Ingredients & Medications & Injectable Products | G6: Medical Devices | H6: A CLINIC | I6: B CLINIC | J6: C CLINIC
A7: K-Beauty (Medical) | B7: ① | C7: Brightening & Skin Tone Correction | D7: • Improve uneven skin tone • Reduce pigmentation, melasma, and sun damage • Achieve luminous and clear complexion | E7: • Pico Laser Toning • Laser Whitening Program • Glutathione IV Therapy • Medical Brightening Ampoule Infusion | F7: • Glutathione • Vitamin C Complex • Tranexamic Acid • Niacinamide | G7: • PicoSure / PicoWay Laser • Nd:YAG Laser • IPL (Lumenis M22) | I7: Full Face Skin Botox Blood Stem Cell Full Face Stem cell intravenous injection | J7: Pico Dual Toning RejuDM Premium Care(24K Gold therapy+Cryo therapy+LDM Rejuran Skin Booster(2 vials)+LED light Rejuran Healer 4cc, Rejuran Eye 2cc, | K7: Brightening & Skin Tone Correction (미백 & 피부톤개선)
B8: ② | C8: Anti-Aging & Skin Rejuvenation | D8: • Restore youthful skin quality • Stimulate collagen and cellular regeneration • mprove fine lines and skin elasticity | E8: • Skin Booster Therapy • PRP (Platelet-Rich Plasma) • Exosome Rejuvenation • Regenerative Laser Therapy | F8: • PDRN (Salmon DNA) • Hyaluronic Acid • Growth Factors • Medical-grade Exosomes | G8: • RF Microneedling Systems • Fractional Rejuvenation Lasers • LED Regenerative Therapy | I8: Blood Stem Cell Full Face Stem cell intravenous injection | J8: Radio-Frequency facial & neck care Juvelook Skin 4cc RejuDM Premium Care(24K Gold therapy+Cryo therapy+LDM Rejuran Skin Booster(2 vials)+LED light Rejuran Healer 4cc, Rejuran Eye 2cc, | K8: Anti-Aging & Skin Rejuvenation (안티에이징&피부재생)
B9: ③ | C9: Lifting & Facial Contouring | D9: • Improve skin sagging and facial laxity • Enhance jawline and facial contour • Non-surgical lifting solutions | E9: • HIFU Lifting • Radiofrequency Skin Tightening • Premium Thread Lifting | F9: • PDO / PLLA Threads • Collagen Stimulating Agents | G9: • Ultherapy (HIFU) • Shurink Universe • InMode (Forma / FX) • Density RF System | I9: Thermage FLX 900 Shot(Face+Neck) 1 vial Sculptra (No restrictions on body part) Blood Stem Cell Full Face Ultherapy HIFU Prime 600 shot Stem cell intravenous injection | J9: Ultherapy Prime 600 shots, Ultherapy Prime 600 shots(Neck), Ultherapy Prime 600 shots(Eye) Thermage 600 shots, Thermage 225 shots(Eye) Rejuran Healer 4cc, Rejuran Eye 2cc, Volumer 200 shots (Neck). Titanium 100 kJ Ultrasound facial & neck care | K9: Lifting & Facial Contouring (리프팅&윤곽개선)
B10: ④ | C10: Wrinkle Reduction & Volume Restoration | D10: • Smooth deep wrinkles • Restore facial volume naturally • Maintain elegant and refined facial harmony | E10: • Premium Dermal Fillers • Collagen Stimulating Injections • Precision Botulinum Therapy | F10: • Juvederm / Restylane (Hyaluronic Acid Fillers) • Sculptra (PLLA) • Botulinum Toxin (Allergan / Nabota) | G10: • Cannula-based Injection • Ultrasound-Guided Precision Injection | I10: 1 vial Sculptra or Juvederm Filler 3cc (No restrictions on body part) Full Face Skin Botox Thermage FLX 900 Shot(Face+Neck) Blood Stem Cell Full Face | J10: Juvelook Skin 4cc RejuDM Premium Care(24K Gold therapy+Cryo therapy+LDM Rejuran Skin Booster(2 vials)+LED light therapy+Modeling pack) Ultrasound facial & neck care | K10: Wrinkle Reduction & Volume Restoration (주름개선&볼륨복원)
B11: ⑤ | C11: Skin Texture, Pores & Scar Repair | D11: • Improve acne scars and enlarged pores • Refine skin texture • Enhance overall skin smoothness | E11: • Fractional Laser Therapy • RF Microneedling • Subcision Therapy • Medical MTS | F11: • PRP • Exosomes • PDRN • Hyaluronic Acid | G11: • Fraxel Laser • Potenza RF Microneedling • CO₂ Laser Systems | I11: Blood Stem Cell Full Face Stem cell intravenous injection Rejuran HB 4cc | J11: Pico Dual Toning Rejuran Healer 4cc, Rejuran Eye 2cc, | K11: Skin Texture, Pores & Scar Repair (피부결,모공,흉터개선)
B12: ⑥ | C12: Regenerative & Recovery Therapy | D12: • Stem-Cell Derived Therapy • Intensive Skin Recovery Program • Post-Procedure Regeneration Care | E12: • Stem-Cell Derived Therapy • Intensive Skin Recovery Program • Post-Procedure Regeneration Care | F12: • Stem Cell Conditioned Media • Exosomes • Centella-based Regenerative Compounds | G12: • LED Healing Therapy • Oxygen Therapy Systems | I12: Blood Stem Cell Full Face Stem cell intravenous injection | K12: Regenerative & Recovery Therapy (재생&회복치료)
B13: ⑦ | C13: Wellness & Aesthetic Medicine | D13: • Holistic beauty and wellness • Anti-aging from within • Physical and mental rejuvenation | E13: • IV Vitamin & Antioxidant Therapy • Detox & Anti-Inflammatory Programs • Body Contouring & Tightening | F13: • Vitamin Complex • Antioxidants • L-Carnitine | G13: • InMode Body • EMS Sculpting Systems • RF Body Tightening Devices | I13: Premium SkinCeuticals Antioxidant Care Rejuran HB 4cc Premium SkinCeuticals(55ml) Ampoule giveaway Stem cell intravenous injection | J13: Rejuran Healer 4cc, Rejuran Eye 2cc, Mega Complex Vitamin IV Therapy Premium Nutrition IV Therapy | K13: Wellness & Aesthetic Medicine (웰니스&메디컬에스테틱)

Sheet (3) Selection_K-Beauty_NonMedi
A1: K-Beauty_Non-Medical Selection Sheet for Schedule
C3: Name (M or F) : | D3: =Cover!$D$69 -> : Michael Hong | G3: Passport No. : | H3: =Cover!$D$73 -> : DMC 0000000000
C4: Birth Date : | D4: =Cover!$D$71 -> : Feb. OO, 197X(Age: 5X) | G4: Arrival Flight Schedule (Local Time): | H4: =Cover!$D$58 -> : Departure - Mar. 10. 2026. 03:30 (Dubai) / Arrival - Mar. 10. 2026. 16:50 (Incheon)
C5: VIPs Contact. : | D5: =_xlfn.TEXTJOIN(" / ", TRUE, Cover!$D$76:$D$77) -> : +971-00-00-000 / : example@example.com | G5: Departure Flight Schedule (Local Time) : | H5: =Cover!$D$59 -> : Departure - Mar. 19. 2026. 23:40 (Incheon) / Arrival - Mar. 20. 2026. 05:05 (Dubai)
A8: Premium Package Category | G8: Check (ex.) | H8: Remarks | I8: Customer Requirement
A9: Package | D9: Package detail | E9: Duration (activity + transfer) | F9: Estimated Price (USD)
A10: K-Beauty (Non-Medical) | B10: Body Therapy | C10: Silver | D10: Purpose * Daily fatigue relief and muscle relaxation * Light recovery without strong stimulation or devices * Entry-level body therapy for first-time spa users Core Inclusions * Manual massage–based body therapy * Medium or light pressure * Partial or basic full-body coverage * No advanced devices or functional slimming technology | E10: 60-120min | F10: 412.53 - 575.96
C11: Gold | D11: Purpose * Deeper muscle recovery and circulation improvement * Body balance, lymphatic flow, and line refinement * Noticeable physical effect beyond relaxation Core Inclusions * Full-body treatment * Medium to deep pressure * Thermal elements, lymphatic techniques, or spa-specific technology * Optional detox or body line–focused care | E11: 90-150min | F11: 539.47 - 1,078.93
C12: Diamond | D12: Purpose * Targeted body transformation or premium sensory experience * Slimming, deep detox, or rare luxury ingredients * Destination-level body therapy Core Inclusions * Full-body ritual or intensive device-based care * Advanced technology (ultrasound, pressure & temperature control) * Long-duration or highly specialized programs | E12: 120-240min | F12: 674.33 - 2,380 | G12: ✔
A15: Premium Package Category | G15: Check (ex.) | H15: Remarks | I15: Customer Requirement
A16: Package | D16: Package detail | E16: Duration (activity + transfer) | F16: Estimated Price (USD)
A17: K-Beauty (Non-Medical) | B17: Signature treatments | C17: Silver | D17: Purpose Recovery-focused signature experience Body therapy + simple facial combination Core Inclusions Warm stone or calming body therapy Short ritual structure Stress & jet lag recovery focus | E17: 120min | F17: 840.93
C18: Gold | D18: Purpose * Emotional relaxation and shared experience * Sensory immersion rather than medical effect Core Inclusions * Multi-step ritual * Body scrub + body therapy * Couple or private suite experience | E18: 150min | F18: 840.93
C19: Diamond | D19: Purpose * Brand-defining spa journey * Cultural storytelling + full ritual experience Core Inclusions * Scrub + detox + body therapy + facial * Long duration * Most comprehensive Signature treatment | E19: 150min | F19: 840.93 | G19: ✔
B20: Facial collection | C20: Silver | D20: Purpose * Skin recovery and rejuvenation * Practical, no-downtime facial care Core Inclusions * Device-based facial technology * Cleansing, hydration, circulation improvement | E20: 90min | F20: 650.53
C21: Gold | D21: Purpose * Personalized skin improvement * Texture, contour, and radiance enhancement Core Inclusions * Skin analysis * Bespoke treatment protocol * Reshaping and hydration care | E21: 90min | F21: 714
C22: Diamond | D22: Purpose * Instant visible results with premium cosmeceutical technology * Flagship facial experience Core Inclusions * Exclusive treatment method (Second Skin) * High-concentration active ingredients * No-downtime, high-impact result | E22: 75min | F22: 888.53 | G22: ✔
A25: Premium Package Category | G25: Check (ex.) | H25: Remarks | I25: Customer Requirement
A26: Package | D26: Package detail | E26: Duration (activity + transfer) | F26: Estimated Price (USD)
A27: K-Beauty (Non-Medical) | B27: Henna | C27: Henna at Seoul | D27: Traditional Indian henna art created using natural henna dye. The design remains on the skin temporarily and fades naturally over time. #Henna #Art #Temporary #Seoul
C28: Henna at Busan | D28: Traditional Indian henna art created using natural henna dye. The design remains on the skin temporarily and fades naturally over time. #Henna #Art #Temporary #Busan | H28: For locations outside Seoul, Incheon, and Gyeonggi-do, travel time may be longer, so we recommend combining this experience with other activities in Busan or Ulsan.
B29: Scalp treatment | D29: A premium scalp care program at Eco Jardin, providing deep cleansing and revitalization of the scalp through delicate care by experienced professionals. The program includes consultation, diagnosis, scalp treatment, and styling. #Premium Scalp Care #Consultation & Diagnosis #Treatment #Styling #Seoul | F29: 396.67 | G29: ✔

Sheet (4-1) Selection_K-Wellness_GEN
A1: K-Wellness_General Selection Sheet for Schedule
D2: Name (M or F) : | E2: =Cover!$D$69 -> : Michael Hong | H2: Passport No. : | I2: =Cover!$D$73 -> : DMC 0000000000
D3: Birth Date : | E3: =Cover!$D$71 -> : Feb. OO, 197X(Age: 5X) | H3: Arrival Flight Schedule (Local Time): | I3: =Cover!$D$58 -> : Departure - Mar. 10. 2026. 03:30 (Dubai) / Arrival - Mar. 10. 2026. 16:50 (Incheon)
D4: VIPs Contact. : | E4: =_xlfn.TEXTJOIN(" / ", TRUE, Cover!$D$76:$D$77) -> : +971-00-00-000 / : example@example.com | H4: Departure Flight Schedule (Local Time) : | I4: =Cover!$D$59 -> : Departure - Mar. 19. 2026. 23:40 (Incheon) / Arrival - Mar. 20. 2026. 05:05 (Dubai)
A7: Premium Package Category | H7: Check (ex.) | I7: Remarks | J7: Customer Requirement
A8: Package | E8: Package detail | F8: Duration (activity + transfer) | G8: Estimated Price (USD)
A9: K-Wellness | B9: Free Time | E9: Personal rest options available (4 hours or full day)
B10: Shopping | C10: Cosmetics & Beauty Products | E10: Korea’s first health and beauty store and the country’s largest H&B retail chain, offering a curated selection of cosmetics, health supplements, beauty products, and popular domestic and international brands in one place. #Cosmetics #Health #Beauty #Olive Young | H10: ✔ | I10: Final purchases are entirely at the customer’s own discretion.
C11: K-GLASSES | E11: A premium optical store founded in 1942, trusted by Korean presidents and VIPs, and Korea’s largest Lindberg dealer, offering advanced eye examinations and high-precision digital lenses with state-of-the-art technology. #Premium Optical Store #Lindberg #Advanced Technology #State-of-the-Art Equipment #KUMKANG OPTICAL | H11: ✔ | I11: Final purchases are entirely at the customer’s own discretion.
C12: Stationery | E12: Korea’s first design-focused stationery brand that redefined stationery as a lifestyle category, offering stylish stationery and everyday lifestyle goods with a strong design identity. #Fancy Goods #Stationery #Lifestyle Products #ARTBOX | I12: Final purchases are entirely at the customer’s own discretion.
B13: K-Pop | C13: Tour | D13: K-POP Demon Hunters | E13: An immersive mission-based adventure across Seoul’s iconic landmarks using cutting-edge XR/AR technology, where participants step into the world of K-POP Demon Hunters. #Private van tour #mission tour #XR/AR #Seoul | F13: 1day | G13: 1,364.53 / 1Group | H13: ✔
D14: K-POP Concert | E14: Attend a live taping of SBS Inkigayo and enjoy a walking tour around the SBS Public Hall area, with itineraries that change monthly. #SBS Inkigayo #K-POP Walking Tour #Seoul Jongro | F14: 1day | G14: 571.2 | I14: Held Every Sunday Passport Required Due to limited ticket availability, participation may not be possible even if this option is selected.
D15: K-Drama Tour (Descendants of the Sun, Guardian: The Lonely and Great God, My Love From the Star) | E15: Visit iconic filming locations from three legendary K-dramas and enjoy everyday Korean life through local cafés and chicken restaurants. #Private Tour #K-Drama Tour #Descendants of the Sun #Guardian: The Lonely and Great God #My Love From the Star #Seoul, Incheon | F15: 1day | G15: 245.14 - 554.54
D16: K-Drama Tour (Welcome to Samdal-ri, Extraordinary Attorney Woo, When Life Gives You Tangerines) | E16: Explore K-drama filming locations across Jeju Island and experience the scenery and stories that brought these dramas to life. #Private Tour #K-Drama Tour #Welcome to Samdal-ri #Extraordinary Attorney Woo #When Life Gives You Tangerines #Jeju island | F16: 2day | G16: 603 | I16: For locations outside Seoul, Incheon, and Gyeonggi-do, travel time may be longer, so we recommend combining this experience with other activities in Jeju.
D17: K-Drama Tour (Squid Game) | E17: Visit real Squid Game filming locations and participate in on-screen missions including dalgona carving, retro lunchbox dining, and themed activities across Incheon. #Mission tour #Squid Game #Incheon | F17: 1day | G17: 366.52
D18: Award Ceremony | E18: Experience the atmosphere of a Korean award ceremony and witness K-POP stars and artists celebrate their achievements live.
A21: Premium Package Category | H21: Check (ex.) | I21: Remarks | J21: Customer Requirement
A22: Package | E22: Package detail | F22: Duration (activity + transfer) | G22: Estimated Price (USD)
A23: K-Wellness | B23: K-Pop | C23: Experience | D23: K-POP Experience | E23: A VIP-only private K-POP program limited to four participants per day, offering dance and vocal training, idol makeup, and concept photo shoots inspired by real debut preparation. #Dance lesson #Vocal lesson #Idol Makeup #Idol Concept Photo Shoot #Seoul | F23: 1day | G23: 855.21
C24: Dance | D24: K-POP Dance Lesson | E24: Fully customized private dance lessons tailored to individual goals, available at your preferred time and location, covering any genre or choreography. #Private lesson #Dance lesson #Choreography Master #Seoul | F24: 180min | G24: 158.67 | I24: Photos and videos may be used for promotional purposes. Led by a professional trainer, with difficulty tailored to participants’ levels.
C25: Beauty | D25: K-POP Fashion | E25: A one-on-one styling experience with a Korean stylist who curates 6–7 outfit recommendations per hour from popular Korean fashion brands, with full freedom to choose final purchases. #Private group #Korean Stylist #Shopping tour #Seoul Gangnam | F25: 180min | G25: 317.33 - 337.96 | H25: ✔
D26: K-POP Styling | E26: Professional K-Beauty styling experience at studios where Korean stars prepare for performances, including makeup, hair styling, and photoshoots. #K-POP Styling #Makeup #Hair Styling #Photoshoot #Seoul | F26: 240min | G26: 1071 | H26: ✔ | I26: Pre-interview required(Google Form)
D27: Style Consulting | E27: Personalized offline consulting to find the most suitable hair, makeup, and fashion style based on individual concerns and desired image. #Private Offline Service #Hair Consulting #Makeup Consulting #Fashion Consulting #Seoul | F27: 300min | G27: 714 | H27: ✔
D28: Personal Color Diagnosis | E28: In-depth personal color and image consulting that defines optimal colors, styling direction, and overall branding for each individual. #Private Consulting #Personal Color #Body Structure Consulting #Image Perfume & Aroma #Seoul | F28: 210min | G28: 952 - 13,962.67 | H28: ✔
B29: Tour | C29: KTX Experience | E29: Experience Korea’s high-speed rail system that connects most regions within two hours, representing the country’s fastest and most efficient mode of travel. | I29: If selected, inter-regional travel will be by train rather than by private vehicle.
C30: Seoul Tour | D30: Seoul City Tour | E30: A full-day premium tour capturing Seoul’s history, culture, nature, and modern cityscape, from royal palaces and traditional streets to urban landmarks and a scenic Han River night view. #VIP Private Tour #Royal Guard change ceremony #Gyeongbokgung Palace #National folk museum of korea #N seoul tower #Changdeokgung palace #Insadong #Han River Cruise #Seoul | F30: 1day | G30: 349.07 | I30: Mondays: Changdeokgung Palace closed -> replace with Bukchon Hanok Village Tuesdays: Gyeongbokgung closed -> replaced with Deoksugung Below -10°C or in case of rain/snow: Royal Guard Changing Ceremony may be canceled In case of strong winds, heavy rain or snow: N Seoul Tower schedule may be canceled
D31: Seoul City Night Tour | E31: Discover Seoul after dark through a scenic drive and relaxed evening walks showcasing illuminated landmarks and vibrant city nightlife. #Gwanghwamun #Cheonggyecheon River #Dongdaemun Design Plaza #N Seoul Tower #Han River #Banpo Grand Bridge Fountain #Itaewon #Seoul | F31: 300min | G31: 142.8 | I31: Passport Required If traffic is restricted due to rallies or demonstrations near Gwanghwamun Square, an alternative itinerary will be arranged.
D32: ISLAMIC Seoul City Tour | E32: A Muslim-only private Seoul tour with halal meals and prayer time arrangements, covering key historical, cultural, and modern landmarks. #Muslim Private Tour #Royal Guard change ceremony #Gyeongbokgung Palace #N seoul tower #Itaewon Mosque #Bukchon Village #Dongdaemun Design Plaza #Gwangjang Market #Myeongdong #Seoul | F32: 1day | G32: 134.87
A35: Premium Package Category | H35: Check (ex.) | I35: Remarks | J35: Customer Requirement
A36: Package | E36: Package detail | F36: Duration (activity + transfer) | G36: Estimated Price (USD)
A37: K-Wellness | B37: Tour | C37: Local Tour | D37: DMZ + NLL Tour | E37: Explore the realities of the Korean Peninsula’s division through visits to the DMZ and NLL, including the Third Tunnel, observatory views of North Korea, and a meeting with a North Korean defector. #DMZ Tour #NLL Tour #North Korea #DMZ,NLL | F37: 1day | G37: 253.87 | H37: ✔ | I37: Mondays & Public Holidays: Closed / Passport required Military situation or severe weather: Alternative route operated (no refunds) Military area rules must be strictly followed / Only authorized buses and military shuttles permitted No independent movement allowed / Photography and video recording prohibited in restricted areas (Military Protection Act)
D38: ISLAMIC NAMI ISLAND TOUR | E38: A Muslim-only private tour to Nami Island with halal meals and prayer time arrangements in a peaceful natural setting. #Muslim Private Tour #Nami island #Gangwon-do | F38: 1day | G38: 190.4 | H38: ✔
D39: Jeju Island Private Tour | E39: A fully customizable luxury Jeju tour with a stay at Grand Hyatt Jeju, combining sightseeing, relaxation, fine dining, yacht cruising, massage, and immersive art experiences. #Private Tour #Yacht #Massage #Jeju Island | F39: 3day | G39: 1,088.45 - 1,848.47 | I39: Round-trip airfare, private vehicle, and driver included. For locations outside Seoul, Incheon, and Gyeonggi-do, travel time may be longer.
D40: Jeju island Golf Tour | E40: A premium golf getaway featuring a private Blackstone Villa Suite stay and multiple rounds at Jeju’s top-tier golf courses, Blackstone CC and Elysian CC. #Golf Tour #Blackstone CC #Elysian CC #Jeju Island | F40: 3day | G40: 1,407.37 - 1,975.40 | I40: Green fees for three 18-hole rounds – 1 round at Elysian, 2 rounds at Blackstone For locations outside Seoul, Incheon, and Gyeonggi-do, travel time may be longer.
D41: Gyeongbuk Tourpass | E41: A convenient all-in-one free-pass granting access to major paid attractions across Gyeongsangbuk-do for 24, 48, or 72 hours with a single barcode. #FreePass #TourismPass #Gyeongju #Pohang #Ulleungdo #More #Gyeongsangbuk-do | F41: 3day | G41: 26.97 | I41: A free-pass style ticket offering complimentary access to selected attractions and partner cafés. No guide, no fixed route For locations outside Seoul, Incheon, and Gyeonggi-do, travel time may be longer
C42: Cruise Tour | D42: Busan Cruise Tour | E42: An unforgettable overnight luxury cruise departing from Busan Port, featuring premium dining, live performances, onboard fireworks, and exclusive duty-free shopping along the Korea Strait. #One-night Cruise #Onboard buffet #Onboard fireworks #Busan | F42: 2day | G42: 1,047.20 - 1,031.33 | I42: Operates every Saturday 1st, 2nd, 4th, and 5th Saturdays: Taejongdae, Molundae, Dongbaekseom, Gwangalli 3rd Saturday: Tsushima Hitakatsu Port – Gwangalli Passport required For locations outside Seoul, Incheon, and Gyeonggi-do, travel time may be longer, so we recommend combining this experience with other activities in Busan or Ulsan.
C43: Rail Cruise Tour | D43: Grand Tour of Korea by Train | E43: A unique overnight sightseeing train journey that combines rail travel and cruise-style comfort, traveling across Korea’s major regions before returning to Seoul. #GrandTour #OvernightTrain #Suncheon #Yeosu #Busan #Gyeongju #Donghae #whole country #Departing from Seoul #Returning to Seoul | F43: 3day | G43: 5,616.80 - 5,886.53 | I43: Train fare, connecting bus fees, onboard accommodation, meals, snacks, beverages, entrance fees, activity fees, and onboard events included.
A46: Premium Package Category | H46: Check (ex.) | I46: Remarks | J46: Customer Requirement
A47: Package | E47: Package detail | F47: Duration (activity + transfer) | G47: Estimated Price (USD)
A48: K-Wellness | B48: Leisure | C48: Snow Park | D48: Ski | E48: Enjoy winter skiing at major resorts in Gangwon-do and Gyeonggi-do, offering slopes for all skill levels with well-equipped facilities. #Winter Sports #Ski rental #Suit rental #Lift #MonaYongPyong #High1 #VivaldiPark #Konjiam #Gangwon-do #Gyeonggi-do | F48: 1-2day | G48: 176.12 - 252.28 | I48: Limited to season If you have a preferred ski resort, please specify it here (e.g., MONA Yongpyong Resort, High1 Resort, Vivaldi Park Resort, KONJIAM Resort). If left blank, we will recommend the best available option for you. For locations outside Seoul, Incheon, and Gyeonggi-do, travel time may be longer.
...

Sheet (4-2) Selection_K-Wellness_SCH
A1: K-Wellness_School Trip Selection Sheet for Schedule
D2: Name (M or F) : | E2: =Cover!$D$69 -> : Michael Hong | H2: Passport No. : | I2: =Cover!$D$73 -> : DMC 0000000000
D3: Birth Date : | E3: =Cover!$D$71 -> : Feb. OO, 197X(Age: 5X) | H3: Arrival Flight Schedule (Local Time): | I3: =Cover!$D$58 -> : Departure - Mar. 10. 2026. 03:30 (Dubai) / Arrival - Mar. 10. 2026. 16:50 (Incheon)
D4: VIPs Contact. : | E4: =_xlfn.TEXTJOIN(" / ", TRUE, Cover!$D$76:$D$77) -> : +971-00-00-000 / : example@example.com | H4: Departure Flight Schedule (Local Time) : | I4: =Cover!$D$59 -> : Departure - Mar. 19. 2026. 23:40 (Incheon) / Arrival - Mar. 20. 2026. 05:05 (Dubai)
A7: Premium Package Category | H7: Check (ex.) | I7: Remarks | J7: Customer Requirement
A8: Package | E8: Package detail | F8: Duration (activity + transfer) | G8: Estimated Price (USD)
A9: K-Wellness | B9: Free Time | E9: Personal rest options available (4 hours or full day)
B10: Shopping | C10: Cosmetics & Beauty Products | E10: Korea’s first health and beauty store and the country’s largest H&B retail chain, offering a curated selection of cosmetics, health supplements, beauty products, and popular domestic and international brands in one place. #Cosmetics #Health #Beauty #Olive Young | H10: ✔ | I10: Final purchases are entirely at the customer’s own discretion.
C11: K-GLASSES | E11: A premium optical store founded in 1942, trusted by Korean presidents and VIPs, and Korea’s largest Lindberg dealer, offering advanced eye examinations and high-precision digital lenses with state-of-the-art technology. #Premium Optical Store #Lindberg #Advanced Technology #State-of-the-Art Equipment #KUMKANG OPTICAL | H11: ✔ | I11: Final purchases are entirely at the customer’s own discretion.
C12: Stationery | E12: Korea’s first design-focused stationery brand that redefined stationery as a lifestyle category, offering stylish stationery and everyday lifestyle goods with a strong design identity. #Fancy Goods #Stationery #Lifestyle Products #ARTBOX | I12: Final purchases are entirely at the customer’s own discretion.
B13: K-Pop | C13: Tour | D13: K-POP Demon Hunters | E13: An immersive mission-based adventure across Seoul’s iconic landmarks using cutting-edge XR/AR technology, where participants step into the world of K-POP Demon Hunters. #Private van tour #mission tour #XR/AR #Seoul | F13: 1day | G13: 1,364.53 / 1Group | H13: ✔
D14: K-POP Concert | E14: Attend a live taping of SBS Inkigayo and enjoy a walking tour around the SBS Public Hall area, with itineraries that change monthly. #SBS Inkigayo #K-POP Walking Tour #Seoul Jongro | F14: 1day | G14: 571.2 | I14: Held Every Sunday Passport Required Due to limited ticket availability, participation may not be possible even if this option is selected.
D15: K-Drama Tour (Descendants of the Sun, Guardian: The Lonely and Great God, My Love From the Star) | E15: Visit iconic filming locations from three legendary K-dramas and enjoy everyday Korean life through local cafés and chicken restaurants. #Private Tour #K-Drama Tour #Descendants of the Sun #Guardian: The Lonely and Great God #My Love From the Star #Seoul, Incheon | F15: 1day | G15: 245.14 - 554.54
D16: K-Drama Tour (Welcome to Samdal-ri, Extraordinary Attorney Woo, When Life Gives You Tangerines) | E16: Explore K-drama filming locations across Jeju Island and experience the scenery and stories that brought these dramas to life. #Private Tour #K-Drama Tour #Welcome to Samdal-ri #Extraordinary Attorney Woo #When Life Gives You Tangerines #Jeju island | F16: 2day | G16: 603 | I16: For locations outside Seoul, Incheon, and Gyeonggi-do, travel time may be longer, so we recommend combining this experience with other activities in Jeju.
D17: K-Drama Tour (Squid Game) | E17: Visit real Squid Game filming locations and participate in on-screen missions including dalgona carving, retro lunchbox dining, and themed activities across Incheon. #Mission tour #Squid Game #Incheon | F17: 1day | G17: 366.52
D18: Award Ceremony | E18: Experience the atmosphere of a Korean award ceremony and witness K-POP stars and artists celebrate their achievements live.
A21: Premium Package Category | H21: Check (ex.) | I21: Remarks | J21: Customer Requirement
A22: Package | E22: Package detail | F22: Duration (activity + transfer) | G22: Estimated Price (USD)
A23: K-Wellness | B23: K-Pop | C23: Experience | D23: K-POP Experience | E23: A VIP-only private K-POP program limited to four participants per day, offering dance and vocal training, idol makeup, and concept photo shoots inspired by real debut preparation. #Dance lesson #Vocal lesson #Idol Makeup #Idol Concept Photo Shoot #Seoul | F23: 1day | G23: 855.21
C24: Dance | D24: K-POP Dance Lesson | E24: Fully customized private dance lessons tailored to individual goals, available at your preferred time and location, covering any genre or choreography. #Private lesson #Dance lesson #Choreography Master #Seoul | F24: 180min | G24: 158.67 | I24: Photos and videos may be used for promotional purposes. Led by a professional trainer, with difficulty tailored to participants’ levels.
C25: Beauty | D25: K-POP Fashion | E25: A one-on-one styling experience with a Korean stylist who curates 6–7 outfit recommendations per hour from popular Korean fashion brands, with full freedom to choose final purchases. #Private group #Korean Stylist #Shopping tour #Seoul Gangnam | F25: 180min | G25: 317.33 - 337.96 | H25: ✔
D26: K-POP Styling | E26: Professional K-Beauty styling experience at studios where Korean stars prepare for performances, including makeup, hair styling, and photoshoots. #K-POP Styling #Makeup #Hair Styling #Photoshoot #Seoul | F26: 240min | G26: 1071 | H26: ✔ | I26: Pre-interview required(Google Form)
D27: Style Consulting | E27: Personalized offline consulting to find the most suitable hair, makeup, and fashion style based on individual concerns and desired image. #Private Offline Service #Hair Consulting #Makeup Consulting #Fashion Consulting #Seoul | F27: 300min | G27: 714 | H27: ✔
D28: Personal Color Diagnosis | E28: In-depth personal color and image consulting that defines optimal colors, styling direction, and overall branding for each individual. #Private Consulting #Personal Color #Body Structure Consulting #Image Perfume & Aroma #Seoul | F28: 210min | G28: 952 - 13,962.67 | H28: ✔
B29: Tour | C29: KTX Experience | E29: Experience Korea’s high-speed rail system that connects most regions within two hours, representing the country’s fastest and most efficient mode of travel. | I29: If selected, inter-regional travel will be by train rather than by private vehicle.
C30: Seoul Tour | D30: Seoul City Tour | E30: A full-day premium tour capturing Seoul’s history, culture, nature, and modern cityscape, from royal palaces and traditional streets to urban landmarks and a scenic Han River night view. #VIP Private Tour #Royal Guard change ceremony #Gyeongbokgung Palace #National folk museum of korea #N seoul tower #Changdeokgung palace #Insadong #Han River Cruise #Seoul | F30: 1day | G30: 349.07 | I30: Mondays: Changdeokgung Palace closed -> replace with Bukchon Hanok Village Tuesdays: Gyeongbokgung closed -> replaced with Deoksugung Below -10°C or in case of rain/snow: Royal Guard Changing Ceremony may be canceled In case of strong winds, heavy rain or snow: N Seoul Tower schedule may be canceled
D31: Seoul City Night Tour | E31: Discover Seoul after dark through a scenic drive and relaxed evening walks showcasing illuminated landmarks and vibrant city nightlife. #Gwanghwamun #Cheonggyecheon River #Dongdaemun Design Plaza #N Seoul Tower #Han River #Banpo Grand Bridge Fountain #Itaewon #Seoul | F31: 300min | G31: 142.8 | I31: Passport Required If traffic is restricted due to rallies or demonstrations near Gwanghwamun Square, an alternative itinerary will be arranged.
D32: ISLAMIC Seoul City Tour | E32: A Muslim-only private Seoul tour with halal meals and prayer time arrangements, covering key historical, cultural, and modern landmarks. #Muslim Private Tour #Royal Guard change ceremony #Gyeongbokgung Palace #N seoul tower #Itaewon Mosque #Bukchon Village #Dongdaemun Design Plaza #Gwangjang Market #Myeongdong #Seoul | F32: 1day | G32: 134.87
A35: Premium Package Category | H35: Check (ex.) | I35: Remarks | J35: Customer Requirement
A36: Package | E36: Package detail | F36: Duration (activity + transfer) | G36: Estimated Price (USD)
A37: K-Wellness | B37: Tour | C37: Local Tour | D37: DMZ + NLL Tour | E37: Explore the realities of the Korean Peninsula’s division through visits to the DMZ and NLL, including the Third Tunnel, observatory views of North Korea, and a meeting with a North Korean defector. #DMZ Tour #NLL Tour #North Korea #DMZ,NLL | F37: 1day | G37: 253.87 | H37: ✔ | I37: Mondays & Public Holidays: Closed / Passport required Military situation or severe weather: Alternative route operated (no refunds) Military area rules must be strictly followed / Only authorized buses and military shuttles permitted No independent movement allowed / Photography and video recording prohibited in restricted areas (Military Protection Act)
D38: ISLAMIC NAMI ISLAND TOUR | E38: A Muslim-only private tour to Nami Island with halal meals and prayer time arrangements in a peaceful natural setting. #Muslim Private Tour #Nami island #Gangwon-do | F38: 1day | G38: 190.4 | H38: ✔
D39: Jeju Island Private Tour | E39: A fully customizable luxury Jeju tour with a stay at Grand Hyatt Jeju, combining sightseeing, relaxation, fine dining, yacht cruising, massage, and immersive art experiences. #Private Tour #Yacht #Massage #Jeju Island | F39: 3day | G39: 1,088.45 - 1,848.47 | I39: Round-trip airfare, private vehicle, and driver included. For locations outside Seoul, Incheon, and Gyeonggi-do, travel time may be longer.
D40: Jeju island Golf Tour | E40: A premium golf getaway featuring a private Blackstone Villa Suite stay and multiple rounds at Jeju’s top-tier golf courses, Blackstone CC and Elysian CC. #Golf Tour #Blackstone CC #Elysian CC #Jeju Island | F40: 3day | G40: 1,407.37 - 1,975.40 | I40: Green fees for three 18-hole rounds – 1 round at Elysian, 2 rounds at Blackstone For locations outside Seoul, Incheon, and Gyeonggi-do, travel time may be longer.
D41: Gyeongbuk Tourpass | E41: A convenient all-in-one free-pass granting access to major paid attractions across Gyeongsangbuk-do for 24, 48, or 72 hours with a single barcode. #FreePass #TourismPass #Gyeongju #Pohang #Ulleungdo #More #Gyeongsangbuk-do | F41: 3day | G41: 26.97 | I41: A free-pass style ticket offering complimentary access to selected attractions and partner cafés. No guide, no fixed route For locations outside Seoul, Incheon, and Gyeonggi-do, travel time may be longer
C42: Cruise Tour | D42: Busan Cruise Tour | E42: An unforgettable overnight luxury cruise departing from Busan Port, featuring premium dining, live performances, onboard fireworks, and exclusive duty-free shopping along the Korea Strait. #One-night Cruise #Onboard buffet #Onboard fireworks #Busan | F42: 2day | G42: 1,047.20 - 1,031.33 | I42: Operates every Saturday 1st, 2nd, 4th, and 5th Saturdays: Taejongdae, Molundae, Dongbaekseom, Gwangalli 3rd Saturday: Tsushima Hitakatsu Port – Gwangalli Passport required For locations outside Seoul, Incheon, and Gyeonggi-do, travel time may be longer, so we recommend combining this experience with other activities in Busan or Ulsan.
C43: Rail Cruise Tour | D43: Grand Tour of Korea by Train | E43: A unique overnight sightseeing train journey that combines rail travel and cruise-style comfort, traveling across Korea’s major regions before returning to Seoul. #GrandTour #OvernightTrain #Suncheon #Yeosu #Busan #Gyeongju #Donghae #whole country #Departing from Seoul #Returning to Seoul | F43: 3day | G43: 5,616.80 - 5,886.53 | I43: Train fare, connecting bus fees, onboard accommodation, meals, snacks, beverages, entrance fees, activity fees, and onboard events included.
A46: Premium Package Category | H46: Check (ex.) | I46: Remarks | J46: Customer Requirement
A47: Package | E47: Package detail | F47: Duration (activity + transfer) | G47: Estimated Price (USD)
A48: K-Wellness | B48: Leisure | C48: Snow Park | D48: Ski | E48: Enjoy winter skiing at major resorts in Gangwon-do and Gyeonggi-do, offering slopes for all skill levels with well-equipped facilities. #Winter Sports #Ski rental #Suit rental #Lift #MonaYongPyong #High1 #VivaldiPark #Konjiam #Gangwon-do #Gyeonggi-do | F48: 1-2day | G48: 176.12 - 252.28 | I48: Limited to season If you have a preferred ski resort, please specify it here (e.g., MONA Yongpyong Resort, High1 Resort, Vivaldi Park Resort, KONJIAM Resort). If left blank, we will recommend the best available option for you. For locations outside Seoul, Incheon, and Gyeonggi-do, travel time may be longer.
...

Sheet (5) Selection_SubPackaging
A1: K-Subpackaging Selection Sheet for Schedule
C3: Name (M or F) : | D3: =Cover!$D$69 -> : Michael Hong | G3: Passport No. : | H3: =Cover!$D$73 -> : DMC 0000000000
C4: Birth Date : | D4: =Cover!$D$71 -> : Feb. OO, 197X(Age: 5X) | G4: Arrival Flight Schedule (Local Time): | H4: =Cover!$D$58 -> : Departure - Mar. 10. 2026. 03:30 (Dubai) / Arrival - Mar. 10. 2026. 16:50 (Incheon)
C5: VIPs Contact. : | D5: =_xlfn.TEXTJOIN(" / ", TRUE, Cover!$D$76:$D$77) -> : +971-00-00-000 / : example@example.com | G5: Departure Flight Schedule (Local Time) : | H5: =Cover!$D$59 -> : Departure - Mar. 19. 2026. 23:40 (Incheon) / Arrival - Mar. 20. 2026. 05:05 (Dubai)
A7: Premium Package Category | F7: Check (ex.) | G7: Remarks | H7: Customer Requirement
A8: Package | D8: Package detail | E8: Estimated Price (USD)
A9: Luxury Hotel | B9: ★5 Hotel | C9: Deluxe | D9: ex) Executive Grand / Premier Double / Premier Family / 2 twin bed premium / 2 double premium / Grand Deluxe Suite | E9: 853.63 - 2,792.53(1night) | G9: If you have a preferred area or hotel, please specify it here. If not specified, a hotel will be arranged based on your itinerary and preferred hotel grade.
C10: Suite | D10: Premier Suite / Park Coner Suite / Coner Suite / Royal Suite / Ambassador Suite | E10: 1,767.55 - 6,632.27(1night) | F10: ✔
C11: Special Suite | D11: Shilla Suite / Presidential Suite / Ambassador Suite / Grand Deluxe / Penthouse | E11: 4,314.15 - 20,626.67(1night)
B12: Hanok | E12: 728.28 - 34,906.67(1night)
A13: Private Vehicle | B13: NOBLE KLASSE SOLATI | C13: NOBLE KLASSE SOLATI S11 | D13: A Muslim-exclusive mobility service using the world’s first halal-certified limousine, featuring an in-vehicle prayer space for seamless Muslim travel in Korea. | G13: If you prefer a private vehicle, please specify the desired vehicle category and the number of vehicles required.
B14: Luxury Sedan | C14: Genesis G90 | E14: 714 - 1,348.67(8hour)
B15: Premium SUV | C15: Benz S580 | E15: 1,269.33 - 1,396.27(8hour) | F15: ✔
B16: Benz Sprinter | E16: 1,269.33 - 2,094.40(8hour)
B17: Limousine Bus
B18: Chauffeur | F18: ✔
A19: Interpreter | B19: General Arabic Interpreter | E19: 1605.71(8hour)
B20: Professional Arabic Interpreter | E20: 3,839.73(8hour) | F20: ✔
A21: Concierge | B21: Personal Concierge | E21: 317.33(1hour) | G21: If you require Concierge services, please specify the dates or schedule for which the service is needed.
A22: Restaurant | B22: Halal-Certified | F22: ✔ | G22: 1 time or 2 time / Day
B23: Acceptable Non-Halal | C23: Seafood
C24: Vegetarian
C25: Others | F25: ✔
B26: Cuisine Type | C26: Korean cuisine
C27: Western / European
C28: Others
B29: Meal preferences | C29: Alcohol-free menu preferred
C30: Hotel breakfast included
C31: Others | F31: ✔
A32: Insurance | E32: 317.33 | F32: ✔
A33: VIP Security | B33: VIP Security | D33: Only Tour & Shopping period | E33: 1,000(10hour) | F33: ✔ | G33: If you require VIP security services, please specify the dates or schedule for which the service is needed.
D34: Tour full days

Sheet Total Quotation Price
A1: Muslim VIP K-BMW Premium Tour ToTal Quotation Price for Schedule
D3: Name (M or F) : | E3: =Cover!$D$69 -> : Michael Hong | G3: Passport No. : | J3: =Cover!$D$73 -> : DMC 0000000000
D4: Birth Date : | E4: =Cover!$D$71 -> : Feb. OO, 197X(Age: 5X) | G4: Arrival Flight Schedule (Local Time): | J4: =Cover!$D$58 -> : Departure - Mar. 10. 2026. 03:30 (Dubai) / Arrival - Mar. 10. 2026. 16:50 (Incheon)
D5: VIPs Contact. : | E5: =_xlfn.TEXTJOIN(" / ", TRUE, Cover!$D$76:$D$77) -> : +971-00-00-000 / : example@example.com | G5: Departure Flight Schedule (Local Time) : | J5: =Cover!$D$59 -> : Departure - Mar. 19. 2026. 23:40 (Incheon) / Arrival - Mar. 20. 2026. 05:05 (Dubai)
I7: Exchange Rate (KRW/USD) | J7: 1500
A9: Premium Package Category
A10: Package | E10: Estimation | G10: Partners Quotation (Cost) | I10: Margin Rate | J10: Agent Fee (Customer Submit)
I11: 0.5 | J11: 0.15 | K11: Comission Fee internal partner
E12: 1,000 KRW | F12: USD | G12: 1,000 KRW | H12: USD | I12: USD | J12: USD
A13: K-Medical | B13: Silver | E13: M: 1,485 - 1,800 F: 1,665 - 2,600 | H13: =G13/$J$7*1000 -> 0 | I13: =H13+H13*$I$11 -> 0 | J13: =I13+I13*$J$77 -> 0
B14: Gold | E14: M: 2,210 - 7,800 F: 2,600 - 8,100 | H14: =G14/$J$7*1000 -> 0 | I14: =H14+H14*$I$77 -> 0 | J14: =I14+I14*$J$77 -> 0
B15: Diamond (Premium) | E15: M: 7,260 - 10,600 F: 7,890- 10,900 | G15: 10900 | H15: =G15/$J$7*1000 -> 7266.6667 | I15: =H15+H15*$I$11 -> 10900 | J15: =I15+I15*$J$77 -> 12535 | K15: =G15*0.15*1000 -> 1635000 | L15: =I15-H15 -> 3633.3333 | M15: =J15-I15 -> 1635
A16: K-Beauty (Medical) | B16: A Clinic | C16: Signiture Program | D16: Salon de Juvénile
D17: Salon de All-Layer
D18: Salon de Sportif
C19: Package | D19: Glow Package | F19: 6666.67 | H19: =G19/$J$7*1000 -> 0 | I19: =H19+H19*$I$77 -> 0 | J19: =I19+I19*$J$77 -> 0
D20: Premium Anti-Aging Package | F20: 13333.33
D21: Premium Stem Cell Anti-Aging Package | F21: 20000 | H21: =G21/$J$7*1000 -> 0 | I21: =H21+H21*$I$77 -> 0 | J21: =I21+I21*$J$77 -> 0
D22: Premiun Body Package | F22: 33333.33 | G22: 15000 | H22: =G22/$J$7*1000 -> 10000 | I22: =H22+H22*$I$77 -> 15000 | J22: =I22+I22*$J$77 -> 17250
B23: B Clinic | C23: Dermatological procedures | D23: Special - 2 | H23: =G23/$J$7*1000 -> 0 | I23: =H23+H23*$I$77 -> 0 | J23: =I23+I23*$J$77 -> 0
D24: Basic | E24: 5,000 / 10,000 / 15,000 | G24: 10000 | H24: =G24/$J$7*1000 -> 6666.6667 | I24: =H24+H24*$I$77 -> 10000 | J24: =I24+I24*$J$77 -> 11500 | K24: =G24*0.15*1000 -> 1500000
D25: Gold | E25: 10,000 / 15,000 / 20,000 | H25: =G25/$J$7*1000 -> 0 | I25: =H25+H25*$I$77 -> 0 | J25: =I25+I25*$J$77 -> 0
D26: Platinum | E26: 15,000 / 20,000 / 25,000 | H26: =G26/$J$7*1000 -> 0 | I26: =H26+H26*$I$77 -> 0 | J26: =I26+I26*$J$77 -> 0
B27: C Clinic | C27: Dermatological procedures | D27: Royal Refresh Day (Face only, no injection) | E27: 5000 | H27: =G27/$J$7*1000 -> 0 | I27: =H27+H27*$I$77 -> 0 | J27: =I27+I27*$J$77 -> 0
D28: Royal Signature Lifting (Including neck & fatigue recovery) | E28: 10000 | H28: =G28/$J$7*1000 -> 0 | I28: =H28+H28*$I$77 -> 0 | J28: =I28+I28*$J$77 -> 0
D29: Royal Face & Body Refinement (Royal Hospital Takeover) | E29: 15000 | G29: 15000 | H29: =G29/$J$7*1000 -> 10000 | I29: =H29+H29*$I$77 -> 15000 | J29: =I29+I29*$J$77 -> 17250
A30: K-Beauty (Non-Medical) | B30: Body Therapy | C30: Silver | E30: 260 - 363 | H30: =G30/$J$7*1000 -> 0 | I30: =H30+H30*$I$77 -> 0 | J30: =I30+I30*$J$77 -> 0
C31: Gold | E31: 340 - 680 | H31: =G31/$J$7*1000 -> 0 | I31: =H31+H31*$I$77 -> 0 | J31: =I31+I31*$J$77 -> 0
C32: Diamond (Premium) | E32: 425 - 1,500 | G32: 1500 | H32: =G32/$J$7*1000 -> 1000 | I32: =H32+H32*$I$77 -> 1500 | J32: =I32+I32*$J$77 -> 1725
B33: Signature treatments | C33: Silver | E33: 530 | H33: =G33/$J$7*1000 -> 0 | I33: =H33+H33*$I$77 -> 0 | J33: =I33+I33*$J$77 -> 0
C34: Gold | E34: 530 | H34: =G34/$J$7*1000 -> 0 | I34: =H34+H34*$I$77 -> 0 | J34: =I34+I34*$J$77 -> 0
C35: Diamond (Premium) | E35: 530 | G35: 530 | H35: =G35/$J$7*1000 -> 353.33333 | I35: =H35+H35*$I$77 -> 530 | J35: =I35+I35*$J$77 -> 609.5
B36: Facial collection | C36: Silver | E36: 410 | H36: =G36/$J$7*1000 -> 0 | I36: =H36+H36*$I$77 -> 0 | J36: =I36+I36*$J$77 -> 0
C37: Gold | E37: 450 | H37: =G37/$J$7*1000 -> 0 | I37: =H37+H37*$I$77 -> 0 | J37: =I37+I37*$J$77 -> 0
C38: Diamond (Premium) | E38: 560 | G38: 560 | H38: =G38/$J$7*1000 -> 373.33333 | I38: =H38+H38*$I$77 -> 560 | J38: =I38+I38*$J$77 -> 644
B39: Henna | H39: =G39/$J$7*1000 -> 0 | I39: =H39+H39*$I$77 -> 0 | J39: =I39+I39*$J$77 -> 0
B40: Scalp treatment | E40: 250 | G40: 250 | H40: =G40/$J$7*1000 -> 166.66667 | I40: =H40+H40*$I$77 -> 250 | J40: =I40+I40*$J$77 -> 287.5
A43: Premium Package Category
A44: Package | E44: Estimation | G44: Partners Quotation (Cost) | I44: Margin Rate | J44: Agent Fee (Customer Submit)
I45: 0.5 | J45: =J11 -> 0.15
...

Sheet Total Price Sheet
A1: Muslim VIP K-BMW Premium Tour ToTal Price Sheet for Schedule
A3: Name (M or F) : | B3: =Cover!$D$69 -> : Michael Hong | C3: Passport No. : | D3: =Cover!$D$73 -> : DMC 0000000000
A4: Birth Date : | B4: =Cover!$D$71 -> : Feb. OO, 197X(Age: 5X) | C4: Arrival Flight Schedule (Local Time): | D4: =Cover!$D$58 -> : Departure - Mar. 10. 2026. 03:30 (Dubai) / Arrival - Mar. 10. 2026. 16:50 (Incheon)
A5: VIPs Contact. : | B5: =_xlfn.TEXTJOIN(" / ", TRUE, Cover!$D$76:$D$77) -> : +971-00-00-000 / : example@example.com | C5: Departure Flight Schedule (Local Time) : | D5: =Cover!$D$59 -> : Departure - Mar. 19. 2026. 23:40 (Incheon) / Arrival - Mar. 20. 2026. 05:05 (Dubai)
C7: Exchange Rate (KRW/USD) | D7: 1500
A9: Premium Package Category
A10: Package | D10: Agent Fee (VIPs Customer Submit Price)
D11: USD
A12: K-Medical | B12: Dimond (Premium) | D12: =SUM('Total Quotation Price'!J13:J15) -> 12535
A13: K-Beauty (Medical) | B13: A Clinic | D13: =SUM('Total Quotation Price'!J23:J26) -> 11500
B14: B Clinic | D14: =SUM('Total Quotation Price'!J26:J28) -> 0
B15: C Clinic | D15: =SUM('Total Quotation Price'!J27:J29) -> 17250
A16: K-Beauty (Non-Medical) | B16: Body Therapy | D16: =SUM('Total Quotation Price'!J30:J32) -> 1725
B17: Signature treatments | D17: =SUM('Total Quotation Price'!J33:J35) -> 609.5
B18: Facial collection | D18: =SUM('Total Quotation Price'!J36:J38) -> 644
B19: Henna | D19: =SUM('Total Quotation Price'!J39) -> 0
B20: Scalp treatment | D20: =SUM('Total Quotation Price'!J40) -> 287.5
A21: K-Wellness | B21: Free Time
B22: Shopping
B23: K-Pop | C23: Tour | D23: =SUM('Total Quotation Price'!J51:J56) -> 494.5
C24: Experience | D24: =SUM('Total Quotation Price'!J57) -> 0
C25: Dance | D25: =SUM('Total Quotation Price'!J58) -> 0
C26: Beauty | D26: =SUM('Total Quotation Price'!J59:J62) -> 10364.95
B27: Tour | C27: Seoul Tour | D27: =SUM('Total Quotation Price'!J63:J65) -> 103.5
C28: Local Tour | D28: =SUM('Total Quotation Price'!J66:J70) -> 644
C29: Busan Cruise Tour | D29: =SUM('Total Quotation Price'!J71) -> 0
C30: Grand Tour of Korea by Train | D30: =SUM('Total Quotation Price'!J72) -> 0
B31: Leisure | C31: Snow park | D31: =SUM('Total Quotation Price'!J79:J81) -> 0
C32: Water Park | D32: =SUM('Total Quotation Price'!J82) -> 0
C33: Barge | D33: =SUM('Total Quotation Price'!J83) -> 0
C34: Sprorts | D34: =SUM('Total Quotation Price'!J84:J85) -> 0
C35: Theme Park | D35: =SUM('Total Quotation Price'!J86) -> 402.5
B36: KTX Experience | D36: =SUM('Total Quotation Price'!J87) -> 0
B37: Education | C37: Package tour | D37: =SUM('Total Quotation Price'!J88:J90) -> 0
C38: It experience | D38: =SUM('Total Quotation Price'!J91:J93) -> 0
C39: Korean University Visit | D39: =SUM('Total Quotation Price'!J94) -> 0
C40: Major Coporation Factory Tour | D40: =SUM('Total Quotation Price'!J95:J97) -> 0
C41: Korean Cultural Experience | D41: =SUM('Total Quotation Price'!J98:J101) -> 0
C42: Korean Heritage Tour | D42: =SUM('Total Quotation Price'!J102) -> 0
C43: Museum Tour | D43: =SUM('Total Quotation Price'!J103:J105) -> 0
...

Sheet INVOICE_to Agent
A1: Commercial Invioce (Example)
B3: To | C3: : OOOO | E3: Ref.NO. | F3: : INTERVIEW-OO-2603-OO
B4: Attention | C4: : | E4: Issue Date | F4: : Feb OO, 2026
B5: C.C | C5: :
B6: From | C6: : Interview Co., Ltd
B8: Subject : K-Beauty & Medical Premium Tour Package for Muslim VIP Clients
G10: Currency: United States Dollars
B11: No | C11: Descriptions | E11: Q'ty | F11: Unit Price | G11: Amount | H11: Remarks
B12: 1 | C12: K-Beauty & Medical Premium Tour Package for Muslim VIP Clients | E12: 1 | F12: ='Total Quotation Price'!I131 -> 112051.85 | G12: =E12*F12 -> 112051.85
B13: Total Amount(USD) | G13: =SUM(G12) -> 112051.85
B15: We are pleased to submit an invoice for the Maharba K-Medi & Beauty and K-Entertainment Tour Package for your VIP clients.
B17: Bank Account Details
A19: 1. | B19: Name of Bank | C19: : SHINHAN BANK
A20: 2. | B20: Account No. | C20: : 180 039 209697
A21: 3. | B21: Address | C21: : 20, SEJONG-DAERO 9-GIL, JUNG-GU, SOUTH KOREA
A22: 4. | B22: Swift Code | C22: : SHBKKRSE
A23: 5. | B23: Beneficiary | C23: : INTERVIEW CO LTD
B24: Beneficiary No. | C24: : +82 10 2396 0469
B26: Yours Faithfully,
B28: Interview Co.,Ltd.
B38: 805ho, 8F, 229 Seokjeong-ro, Michuhol-gu, | D38: Tel: +82-32-715-7899
B39: Incheon, Republic of Korea | D39: Fax: +82-32-715-7946 | G39: www.interviewcorp.co.kr
D40: Email: info@interviewcorp.co.kr

Sheet Travel schedule_cover
B2: Premium Experience
B4: 10-DAY VIP
B5: K-Beauty & Medical Tour
B7: K-Medical · K-Beauty · K-Wellness
E9: DXB | I9: ICN | N9: DXB
B11: March 10-19, 2026
B12: Secoul & Incheon, South Korea
B15: 10-DAY VIP Tour Overview
B17: K-Medical · K-Beauty · K-Wellness
D20: Arrival & Welcome | K20: Precision Health Assessment — Part I
D21: ● | E21: Incheon arrival | K21: ● | L21: Comprehensive health screening
D22: ● | E22: Oackwood Premier Incheon check-in | K22: ● | L22: VIP hospital stay
D27: Precision Health Assessment — Part II | K27: Precision Health Assessment — Part III
D28: ● | E28: Health screening & Colonoscopy | K28: ● | L28: PET-CT imaging
K29: ● | L29: Signiel Seoul check-in
D34: Style Consulting & Shopping Experience | K34: Comprehensive Skin Rejuvenation
D35: ● | E35: Hair, Makeup, fashion styling | K35: ● | L35: Personalized aesthetic program
D36: ● | E36: Stylist-accompanied shopping tour
D37: ● | E37: glasses, cosmetic shopping
D41: Leisure & Recovery | K41: Heritage & History
